Workbook

Sheet source matrix sap
A1: Country Grouping | B1: Country | D1: Machine Line | E1: Primary Source | F1: Secondary source | G1: CRP source | H1: Change Indicator
A2: EUC | B2: Rest of Europe Central | C2: 300 | D2: Compact Excavators | E2: FIL | G2: CEE
A3: EUC | B3: Rest of Europe Central | C3: 310 | D3: GPE Crawler Excavators | E3: FIL | G3: CEE
A4: EUC | B4: Rest of Europe Central | C4: 320 | D4: GPE Wheel Excavators | E4: FIL | G4: CEE
A5: EUC | B5: Rest of Europe Central | C5: 330 | D5: Articulated Haulers | E5: FIL | G5: CEE
A6: EUC | B6: Rest of Europe Central | C6: 340 | D6: Rigid Haulers | E6: FIL | G6: CEE
A7: EUC | B7: Rest of Europe Central | C7: 350 | D7: Compact Wheel Loaders | E7: FIL | G7: CEE
A8: EUC | B8: Rest of Europe Central | C8: 360 | D8: GPE Wheel Loaders | E8: FIL | G8: CEE
A9: EUC | B9: Rest of Europe Central | C9: 380 | D9: Motor Graders | E9: FIL | G9: CEE
A10: EUC | B10: Rest of Europe Central | C10: 390 | D10: Compaction Machines | E10: FIL
A11: EUC | B11: Rest of Europe Central | C11: 400 | D11: Paving Machines | E11: FIL | G11: HVE
A12: EUC | B12: Rest of Europe Central | C12: 410 | D12: Backhoe Loaders | E12: FIL | G12: CEE
A13: EUC | B13: Rest of Europe Central | C13: 420 | D13: Skid Steer Loaders | E13: FIL
A14: EUNW | B14: Rest of Europe North | C14: 300 | D14: Compact Excavators | E14: FIL | G14: CEE
A15: EUNW | B15: Rest of Europe North | C15: 310 | D15: GPE Crawler Excavators | E15: FIL | G15: CEE
A16: EUNW | B16: Rest of Europe North | C16: 320 | D16: GPE Wheel Excavators | E16: FIL | G16: CEE
A17: EUNW | B17: Rest of Europe North | C17: 330 | D17: Articulated Haulers | E17: FIL | G17: CEE
A18: EUNW | B18: Rest of Europe North | C18: 340 | D18: Rigid Haulers | E18: FIL | G18: CEE
A19: EUNW | B19: Rest of Europe North | C19: 350 | D19: Compact Wheel Loaders | E19: FIL | G19: CEE
A20: EUNW | B20: Rest of Europe North | C20: 360 | D20: GPE Wheel Loaders | E20: FIL | G20: CEE
A21: EUNW | B21: Rest of Europe North | C21: 380 | D21: Motor Graders | E21: FIL | G21: CEE
A22: EUNW | B22: Rest of Europe North | C22: 390 | D22: Compaction Machines | E22: FIL
A23: EUNW | B23: Rest of Europe North | C23: 400 | D23: Paving Machines | E23: FIL | G23: HVE
A24: EUNW | B24: Rest of Europe North | C24: 410 | D24: Backhoe Loaders | E24: FIL | G24: CEE
A25: EUNW | B25: Rest of Europe North | C25: 420 | D25: Skid Steer Loaders | E25: FIL
A26: EUS | B26: Rest of Europe South | C26: 300 | D26: Compact Excavators | E26: FIL | G26: CEE
A27: EUS | B27: Rest of Europe South | C27: 310 | D27: GPE Crawler Excavators | E27: FIL | G27: CEE
A28: EUS | B28: Rest of Europe South | C28: 320 | D28: GPE Wheel Excavators | E28: FIL | G28: CEE
A29: EUS | B29: Rest of Europe South | C29: 330 | D29: Articulated Haulers | E29: FIL | G29: CEE
A30: EUS | B30: Rest of Europe South | C30: 340 | D30: Rigid Haulers | E30: FIL | G30: CEE
A31: EUS | B31: Rest of Europe South | C31: 350 | D31: Compact Wheel Loaders | E31: FIL | G31: CEE
A32: EUS | B32: Rest of Europe South | C32: 360 | D32: GPE Wheel Loaders | E32: FIL | G32: CEE
A33: EUS | B33: Rest of Europe South | C33: 380 | D33: Motor Graders | E33: FIL | G33: CEE
A34: EUS | B34: Rest of Europe South | C34: 390 | D34: Compaction Machines | E34: FIL
A35: EUS | B35: Rest of Europe South | C35: 400 | D35: Paving Machines | E35: FIL | G35: HVE
A36: EUS | B36: Rest of Europe South | C36: 410 | D36: Backhoe Loaders | E36: FIL | G36: CEE
A37: EUS | B37: Rest of Europe South | C37: 420 | D37: Skid Steer Loaders | E37: FIL
A38: GAE | B38: UAE | C38: 300 | D38: Compact Excavators | E38: FIL | G38: HVE
A39: GAE | B39: UAE | C39: 310 | D39: GPE Crawler Excavators | E39: FIL | G39: HVE
A40: GAE | B40: UAE | C40: 320 | D40: GPE Wheel Excavators | E40: FIL | G40: HVE
...

Sheet source matrix 2024
A1: country_grouping | B1: country_name | C1: machine_line_code | D1: machine_line_name | E1: Artificial machine line | F1: primary_source | G1: secondary_source | H1: crp_source | I1: change_indicator
A2: GCR | B2: Costa Rica | C2: 300 | D2: Compact Excavators | E2: CEX | F2: PIN | H2: HVE
A3: GCR | B3: Costa Rica | C3: 310 | D3: GPE Crawler Excavators | E3: GEC | F3: PIN | H3: HVE
A4: GCR | B4: Costa Rica | C4: 320 | D4: GPE Wheel Excavators | E4: GEW | F4: PIN | H4: HVE
A5: GCR | B5: Costa Rica | C5: 330 | D5: Articulated Haulers | E5: Articulated Haulers | F5: PIN | H5: HVE
A6: GCR | B6: Costa Rica | C6: 340 | D6: Rigid Haulers | E6: Rigid Haulers | F6: PIN | H6: HVE
A7: GCR | B7: Costa Rica | C7: 350 | D7: Compact Wheel Loaders | E7: WLO | F7: PIN | H7: HVE
A8: GCR | B8: Costa Rica | C8: 360 | D8: GPE Wheel Loaders | E8: WLO | F8: PIN | H8: HVE
A9: GCR | B9: Costa Rica | C9: 380 | D9: Motor Graders | E9: Motor Graders | F9: PIN | H9: HVE
A10: GCR | B10: Costa Rica | C10: 390 | D10: Compaction Machines | E10: Compaction Machines | F10: PIN
A11: GCR | B11: Costa Rica | C11: 410 | D11: Backhoe Loaders | E11: Backhoe Loaders | F11: PIN
A12: GEC | B12: Ecuador | C12: 300 | D12: Compact Excavators | E12: CEX | F12: PIN | H12: HVE
A13: GEC | B13: Ecuador | C13: 310 | D13: GPE Crawler Excavators | E13: GEC | F13: PIN | H13: HVE
A14: GEC | B14: Ecuador | C14: 320 | D14: GPE Wheel Excavators | E14: GEW | F14: PIN | H14: HVE
A15: GEC | B15: Ecuador | C15: 330 | D15: Articulated Haulers | E15: Articulated Haulers | F15: PIN | H15: HVE
A16: GEC | B16: Ecuador | C16: 340 | D16: Rigid Haulers | E16: Rigid Haulers | F16: PIN | H16: HVE
A17: GEC | B17: Ecuador | C17: 350 | D17: Compact Wheel Loaders | E17: WLO | F17: PIN | H17: HVE
A18: GEC | B18: Ecuador | C18: 360 | D18: GPE Wheel Loaders | E18: WLO | F18: PIN | H18: HVE
A19: GEC | B19: Ecuador | C19: 380 | D19: Motor Graders | E19: Motor Graders | F19: PIN | H19: HVE
A20: GEC | B20: Ecuador | C20: 390 | D20: Compaction Machines | E20: Compaction Machines | F20: PIN
A21: GEC | B21: Ecuador | C21: 410 | D21: Backhoe Loaders | E21: Backhoe Loaders | F21: PIN
A22: GGR | B22: Greece | C22: 300 | D22: Compact Excavators | E22: CEX | F22: OHR | H22: CEE
A23: GGR | B23: Greece | C23: 310 | D23: GPE Crawler Excavators | E23: GEC | F23: OHR | H23: CEE
A24: GGR | B24: Greece | C24: 320 | D24: GPE Wheel Excavators | E24: GEW | F24: OHR | H24: CEE
A25: GGR | B25: Greece | C25: 330 | D25: Articulated Haulers | E25: Articulated Haulers | F25: OHR | H25: CEE
A26: GGR | B26: Greece | C26: 340 | D26: Rigid Haulers | E26: Rigid Haulers | F26: OHR | H26: CEE
A27: GGR | B27: Greece | C27: 350 | D27: Compact Wheel Loaders | E27: WLO | F27: OHR | H27: CEE
A28: GGR | B28: Greece | C28: 360 | D28: GPE Wheel Loaders | E28: WLO | F28: OHR | H28: CEE
A29: GGR | B29: Greece | C29: 380 | D29: Motor Graders | E29: Motor Graders | F29: OHR | H29: CEE
A30: GGR | B30: Greece | C30: 390 | D30: Compaction Machines | E30: Compaction Machines
A31: GGT | B31: Guatemala | C31: 300 | D31: Compact Excavators | E31: CEX | F31: PIN | H31: HVE
A32: GGT | B32: Guatemala | C32: 310 | D32: GPE Crawler Excavators | E32: GEC | F32: PIN | H32: HVE
A33: GGT | B33: Guatemala | C33: 320 | D33: GPE Wheel Excavators | E33: GEW | F33: PIN | H33: HVE
A34: GGT | B34: Guatemala | C34: 330 | D34: Articulated Haulers | E34: Articulated Haulers | F34: PIN | H34: HVE
A35: GGT | B35: Guatemala | C35: 340 | D35: Rigid Haulers | E35: Rigid Haulers | F35: PIN | H35: HVE
A36: GGT | B36: Guatemala | C36: 350 | D36: Compact Wheel Loaders | E36: WLO | F36: PIN | H36: HVE
A37: GGT | B37: Guatemala | C37: 360 | D37: GPE Wheel Loaders | E37: WLO | F37: PIN | H37: HVE
A38: GGT | B38: Guatemala | C38: 380 | D38: Motor Graders | E38: Motor Graders | F38: PIN | H38: HVE
A39: GGT | B39: Guatemala | C39: 390 | D39: Compaction Machines | E39: Compaction Machines | F39: PIN
A40: GGT | B40: Guatemala | C40: 410 | D40: Backhoe Loaders | E40: Backhoe Loaders | F40: PIN
...

Sheet CRP TMA
A1: Source | B1: Country Grouping | C1: Country | D1: Market Area | E1: Machine Line | F1: Size Class Flag | G1: Brand Code | H1: FID | I1: TM FID | J1: check sap | K1: check 2024
A2: TMA | B2: Algeria | C2: Algeria | D2: # | E2: Articulated Haulers | F2: Not assigned | G2: # | H2: 0 | I2: 12 | J2: =IF(COUNTIFS('source matrix sap'!$B:$B,$B2,'source matrix sap'!$D:$D,$E2)>0,1,0) -> 1 | K2: =IF(COUNTIFS('source matrix 2024'!$B:$B,$B2,'source matrix 2024'!$D:$D,$E2)>0,1,0) -> 0
A3: TMA | B3: Algeria | C3: Algeria | D3: # | E3: Backhoe Loaders | F3: Not assigned | G3: # | H3: 0 | I3: 80 | J3: =IF(COUNTIFS('source matrix sap'!$B:$B,$B3,'source matrix sap'!$D:$D,$E3)>0,1,0) -> 1 | K3: =IF(COUNTIFS('source matrix 2024'!$B:$B,$B3,'source matrix 2024'!$D:$D,$E3)>0,1,0) -> 0
A4: TMA | B4: Algeria | C4: Algeria | D4: # | E4: Compact Excavators | F4: <6t | G4: # | H4: 0 | I4: 78 | J4: =IF(COUNTIFS('source matrix sap'!$B:$B,$B4,'source matrix sap'!$D:$D,$E4)>0,1,0) -> 1 | K4: =IF(COUNTIFS('source matrix 2024'!$B:$B,$B4,'source matrix 2024'!$D:$D,$E4)>0,1,0) -> 0
A5: TMA | B5: Algeria | C5: Algeria | D5: # | E5: Compact Wheel Loaders | F5: 10<12 | G5: # | H5: 0 | I5: 12 | J5: =IF(COUNTIFS('source matrix sap'!$B:$B,$B5,'source matrix sap'!$D:$D,$E5)>0,1,0) -> 1 | K5: =IF(COUNTIFS('source matrix 2024'!$B:$B,$B5,'source matrix 2024'!$D:$D,$E5)>0,1,0) -> 0
A6: TMA | B6: Algeria | C6: Algeria | D6: # | E6: Compaction Machines | F6: Not assigned | G6: # | H6: 0 | I6: 137 | J6: =IF(COUNTIFS('source matrix sap'!$B:$B,$B6,'source matrix sap'!$D:$D,$E6)>0,1,0) -> 1 | K6: =IF(COUNTIFS('source matrix 2024'!$B:$B,$B6,'source matrix 2024'!$D:$D,$E6)>0,1,0) -> 0
A7: TMA | B7: Algeria | C7: Algeria | D7: # | E7: GPE Crawler Excavators | F7: >10t | G7: # | H7: 0 | I7: 255 | J7: =IF(COUNTIFS('source matrix sap'!$B:$B,$B7,'source matrix sap'!$D:$D,$E7)>0,1,0) -> 1 | K7: =IF(COUNTIFS('source matrix 2024'!$B:$B,$B7,'source matrix 2024'!$D:$D,$E7)>0,1,0) -> 0
A8: TMA | B8: Algeria | C8: Algeria | D8: # | E8: GPE Wheel Excavators | F8: >11t | G8: # | H8: 0 | I8: 9 | J8: =IF(COUNTIFS('source matrix sap'!$B:$B,$B8,'source matrix sap'!$D:$D,$E8)>0,1,0) -> 1 | K8: =IF(COUNTIFS('source matrix 2024'!$B:$B,$B8,'source matrix 2024'!$D:$D,$E8)>0,1,0) -> 0
A9: TMA | B9: Algeria | C9: Algeria | D9: # | E9: GPE Wheel Loaders | F9: >12 | G9: # | H9: 0 | I9: 254 | J9: =IF(COUNTIFS('source matrix sap'!$B:$B,$B9,'source matrix sap'!$D:$D,$E9)>0,1,0) -> 1 | K9: =IF(COUNTIFS('source matrix 2024'!$B:$B,$B9,'source matrix 2024'!$D:$D,$E9)>0,1,0) -> 0
A10: TMA | B10: Algeria | C10: Algeria | D10: # | E10: Motor Graders | F10: Not assigned | G10: # | H10: 0 | I10: 72 | J10: =IF(COUNTIFS('source matrix sap'!$B:$B,$B10,'source matrix sap'!$D:$D,$E10)>0,1,0) -> 1 | K10: =IF(COUNTIFS('source matrix 2024'!$B:$B,$B10,'source matrix 2024'!$D:$D,$E10)>0,1,0) -> 0
A11: TMA | B11: Algeria | C11: Algeria | D11: # | E11: Paving Machines | F11: Not assigned | G11: # | H11: 0 | I11: 25 | J11: =IF(COUNTIFS('source matrix sap'!$B:$B,$B11,'source matrix sap'!$D:$D,$E11)>0,1,0) -> 1 | K11: =IF(COUNTIFS('source matrix 2024'!$B:$B,$B11,'source matrix 2024'!$D:$D,$E11)>0,1,0) -> 0
A12: TMA | B12: Algeria | C12: Algeria | D12: # | E12: Rigid Haulers | F12: Not assigned | G12: # | H12: 0 | I12: 4 | J12: =IF(COUNTIFS('source matrix sap'!$B:$B,$B12,'source matrix sap'!$D:$D,$E12)>0,1,0) -> 1 | K12: =IF(COUNTIFS('source matrix 2024'!$B:$B,$B12,'source matrix 2024'!$D:$D,$E12)>0,1,0) -> 0
A13: TMA | B13: Algeria | C13: Algeria | D13: # | E13: Skid Steer Loaders | F13: Not assigned | G13: # | H13: 0 | I13: 29 | J13: =IF(COUNTIFS('source matrix sap'!$B:$B,$B13,'source matrix sap'!$D:$D,$E13)>0,1,0) -> 1 | K13: =IF(COUNTIFS('source matrix 2024'!$B:$B,$B13,'source matrix 2024'!$D:$D,$E13)>0,1,0) -> 0
... A2108: TMA | B2108: VietNam | C2108: VietNam | D2108: # | E2108: Skid Steer Loaders | F2108: Not assigned | G2108: # | H2108: 0 | I2108: 33 | J2108: =IF(COUNTIFS('source matrix sap'!$B:$B,$B2108,'source matrix sap'!$D:$D,$E2108)>0,1,0) -> 1 | K2108: =IF(COUNTIFS('source matrix 2024'!$B:$B,$B2108,'source matrix 2024'!$D:$D,$E2108)>0,1,0) -> 0

Sheet  TMC TMA preparation
A1: Country Grouping | C1: Country | D1: Region | E1: Machine Line | G1: Size Class Flag | H1: Brand Code | I1: Reporter Flag | J1: Pri/Sec | K1: Source | L1: FID | M1: MS (%) | N1: TM | O1: VCE FID | P1: TM Non-VCE
A2: GAE | B2: UAE | C2: UAE | D2: Region International | E2: 300 | F2: Compact Excavators | G2: 6<10T | H2: # | I2: # | J2: # | K2: TMA | L2: 0 | M2: 0 | N2: 4 | O2: 2 | P2: 2
A3: GAE | B3: UAE | C3: UAE | D3: Region International | E3: 300 | F3: Compact Excavators | G3: 6<11T | H3: # | I3: # | J3: # | K3: TMA | L3: 0 | M3: 0 | N3: 2 | O3: 0 | P3: 2 | Q3: missing
A4: GAE | B4: UAE | C4: UAE | D4: Region International | E4: 300 | F4: Compact Excavators | G4: <6T | H4: # | I4: # | J4: # | K4: TMA | L4: 0 | M4: 0 | N4: 298 | O4: 1 | P4: 297 | Q4: Paving Machines
A5: GAE | B5: UAE | C5: UAE | D5: Region International | E5: 310 | F5: GPE Crawler Excavators | G5: >10T | H5: # | I5: # | J5: # | K5: TMA | L5: 0 | M5: 0 | N5: 1695 | O5: 55 | P5: 1640
A6: GAE | B6: UAE | C6: UAE | D6: Region International | E6: 320 | F6: GPE Wheel Excavators | G6: >11T | H6: # | I6: # | J6: # | K6: TMA | L6: 0 | M6: 0 | N6: 178 | O6: 28 | P6: 150
A7: GAE | B7: UAE | C7: UAE | D7: Region International | E7: 330 | F7: Articulated Haulers | G7: # | H7: # | I7: # | J7: # | K7: TMA | L7: 0 | M7: 0 | N7: 231 | O7: 129 | P7: 102
A8: GAE | B8: UAE | C8: UAE | D8: Region International | E8: 340 | F8: Rigid Haulers | G8: # | H8: # | I8: # | J8: # | K8: TMA | L8: 0 | M8: 0 | N8: 124 | O8: 0 | P8: 124
A9: GAE | B9: UAE | C9: UAE | D9: Region International | E9: 350 | F9: Compact Wheel Loaders | G9: 10<12 | H9: # | I9: # | J9: # | K9: TMA | L9: 0 | M9: 0 | N9: 59 | O9: 0 | P9: 59
A10: GAE | B10: UAE | C10: UAE | D10: Region International | E10: 350 | F10: Compact Wheel Loaders | G10: 7<10 | H10: # | I10: # | J10: # | K10: TMA | L10: 0 | M10: 0 | N10: 2 | O10: 1 | P10: 1
A11: GAE | B11: UAE | C11: UAE | D11: Region International | E11: 350 | F11: Compact Wheel Loaders | G11: <7 | H11: # | I11: # | J11: # | K11: TMA | L11: 0 | M11: 0 | N11: 12 | O11: 0 | P11: 12
A12: GAE | B12: UAE | C12: UAE | D12: Region International | E12: 360 | F12: GPE Wheel Loaders | G12: >12 | H12: # | I12: # | J12: # | K12: TMA | L12: 0 | M12: 0 | N12: 1233 | O12: 160 | P12: 1073
A13: GAE | B13: UAE | C13: UAE | D13: Region International | E13: 380 | F13: Motor Graders | G13: # | H13: # | I13: # | J13: # | K13: TMA | L13: 0 | M13: 0 | N13: 261 | O13: 8 | P13: 253
A14: GAE | B14: UAE | C14: UAE | D14: Region International | E14: 390 | F14: Compaction Machines | G14: # | H14: # | I14: # | J14: # | K14: TMA | L14: 0 | M14: 0 | N14: 431 | O14: 7 | P14: 424
A15: GAE | B15: UAE | C15: UAE | D15: Region International | E15: 400 | F15: Paving Machines | G15: # | H15: # | I15: # | J15: # | K15: TMA | L15: 0 | M15: 0 | N15: 37 | O15: 3 | P15: 34
A16: GAE | B16: UAE | C16: UAE | D16: Region International | E16: 410 | F16: Backhoe Loaders | G16: # | H16: # | I16: # | J16: # | K16: TMA | L16: 0 | M16: 0 | N16: 937 | O16: 2 | P16: 935
... A714: GZA | B714: South Africa | C714: South Africa | D714: Region International | E714: 410 | F714: Backhoe Loaders | G714: # | H714: # | I714: # | J714: # | K714: TMA | L714: 0 | M714: 0 | N714: 1491 | O714: 0 | P714: 1491

Sheet TMA 2024
A1: year | B1: geographical_region | C1: geographical_market_area | D1: end_country | E1: end_country_code | F1: machine_family | G1: machine_line | H1: machine_line_code | I1: size_class | J1: size_class_mapping | K1: total_market_fid_sales
A2: 2024 | B2: Region Asia | C2: MA Asia East | D2: Brunei Darussa | E2: BN | F2: Compact Equipment | G2: Compact Excavators | H2: CEX | I2: EC1<2 | J2: <6T | K2: 0
A3: 2024 | B3: Region Asia | C3: MA Asia East | D3: Brunei Darussa | E3: BN | F3: Compact Equipment | G3: Compact Excavators | H3: CEX | I3: EC3<4 | J3: <6T | K3: 0
A4: 2024 | B4: Region Asia | C4: MA Asia East | D4: Brunei Darussa | E4: BN | F4: Compact Equipment | G4: Compact Excavators | H4: CEX | I4: EC6<8 | J4: 6<10T | K4: 1
A5: 2024 | B5: Region Asia | C5: MA Asia East | D5: Brunei Darussa | E5: BN | F5: General Purpose Equipment | G5: GPE Crawler Excavators | H5: 310 | I5: EC10<14 | J5: >10T | K5: 0
A6: 2024 | B6: Region Asia | C6: MA Asia East | D6: Brunei Darussa | E6: BN | F6: General Purpose Equipment | G6: GPE Crawler Excavators | H6: 310 | I6: EC19<21 | J6: >10T | K6: 2
A7: 2024 | B7: Region Asia | C7: MA Asia East | D7: Brunei Darussa | E7: BN | F7: General Purpose Equipment | G7: GPE Crawler Excavators | H7: 310 | I7: EC21<24 | J7: >10T | K7: 1
A8: 2024 | B8: Region Asia | C8: MA Asia East | D8: Brunei Darussa | E8: BN | F8: General Purpose Equipment | G8: GPE Crawler Excavators | H8: 310 | I8: EC33<40 | J8: >10T | K8: 1
A9: 2024 | B9: Region Asia | C9: MA Asia East | D9: Brunei Darussa | E9: BN | F9: General Purpose Equipment | G9: GPE Wheel Loaders | H9: 360 | I9: WLC16<17 | J9: >12 | K9: 0
A10: 2024 | B10: Region Asia | C10: MA Asia East | D10: Brunei Darussa | E10: BN | F10: Road Machinery Equipment | G10: Compaction Machines | H10: 390 | I10: VS-SS8<12 | J10: Compaction Machines | K10: 0
A11: 2024 | B11: Region Asia | C11: MA Asia East | D11: Japan | E11: JP | F11: Compact Equipment | G11: Compact Excavators | H11: CEX | I11: EC0<1 | J11: <6T | K11: 2583
A12: 2024 | B12: Region Asia | C12: MA Asia East | D12: Japan | E12: JP | F12: Compact Equipment | G12: Compact Excavators | H12: CEX | I12: EC1<2 | J12: <6T | K12: 4055
A13: 2024 | B13: Region Asia | C13: MA Asia East | D13: Japan | E13: JP | F13: Compact Equipment | G13: Compact Excavators | H13: CEX | I13: EC2<3 | J13: <6T | K13: 4875
A14: 2024 | B14: Region Asia | C14: MA Asia East | D14: Japan | E14: JP | F14: Compact Equipment | G14: Compact Excavators | H14: CEX | I14: EC3<4 | J14: <6T | K14: 7885
A15: 2024 | B15: Region Asia | C15: MA Asia East | D15: Japan | E15: JP | F15: Compact Equipment | G15: Compact Excavators | H15: CEX | I15: EC4<5 | J15: <6T | K15: 3237
A16: 2024 | B16: Region Asia | C16: MA Asia East | D16: Japan | E16: JP | F16: Compact Equipment | G16: Compact Excavators | H16: CEX | I16: EC5<6 | J16: <6T | K16: 2001
A17: 2024 | B17: Region Asia | C17: MA Asia East | D17: Japan | E17: JP | F17: Compact Equipment | G17: Compact Excavators | H17: CEX | I17: EC6<8 | J17: 6<10T | K17: 4973
A18: 2024 | B18: Region Asia | C18: MA Asia East | D18: Japan | E18: JP | F18: Compact Equipment | G18: Compact Excavators | H18: CEX | I18: EC8<10 | J18: 6<10T | K18: 820
A19: 2024 | B19: Region Asia | C19: MA Asia East | D19: Japan | E19: JP | F19: Compact Equipment | G19: Compact Excavators | H19: CEX | I19: EW0<6 | J19: <6T | K19: 4
A20: 2024 | B20: Region Asia | C20: MA Asia East | D20: Japan | E20: JP | F20: Compact Equipment | G20: Compact Wheel Loaders | H20: 350 | I20: WLC0<5 | J20: <7 | K20: 5449
A21: 2024 | B21: Region Asia | C21: MA Asia East | D21: Japan | E21: JP | F21: Compact Equipment | G21: Compact Wheel Loaders | H21: 350 | I21: WLC10<12 | J21: 10<12 | K21: 3010
A22: 2024 | B22: Region Asia | C22: MA Asia East | D22: Japan | E22: JP | F22: Compact Equipment | G22: Compact Wheel Loaders | H22: 350 | I22: WLC12<13 | J22: >12 | K22: 380
A23: 2024 | B23: Region Asia | C23: MA Asia East | D23: Japan | E23: JP | F23: Compact Equipment | G23: Compact Wheel Loaders | H23: 350 | I23: WLC5<6 | J23: <7 | K23: 933
A24: 2024 | B24: Region Asia | C24: MA Asia East | D24: Japan | E24: JP | F24: Compact Equipment | G24: Compact Wheel Loaders | H24: 350 | I24: WLC6<7 | J24: <7 | K24: 60
A25: 2024 | B25: Region Asia | C25: MA Asia East | D25: Japan | E25: JP | F25: Compact Equipment | G25: Compact Wheel Loaders | H25: 350 | I25: WLC7<8 | J25: 7<10 | K25: 789
A26: 2024 | B26: Region Asia | C26: MA Asia East | D26: Japan | E26: JP | F26: Compact Equipment | G26: Compact Wheel Loaders | H26: 350 | I26: WLC8<9 | J26: 7<10 | K26: 536
A27: 2024 | B27: Region Asia | C27: MA Asia East | D27: Japan | E27: JP | F27: Compact Equipment | G27: Compact Wheel Loaders | H27: 350 | I27: WLC9<10 | J27: 7<10 | K27: 88
A28: 2024 | B28: Region Asia | C28: MA Asia East | D28: Japan | E28: JP | F28: General Purpose Equipment | G28: Articulated Haulers | H28: 330 | I28: AH0<26 | J28: Articulated Haulers | K28: 29
A29: 2024 | B29: Region Asia | C29: MA Asia East | D29: Japan | E29: JP | F29: General Purpose Equipment | G29: Articulated Haulers | H29: 330 | I29: AH26<30 | J29: Articulated Haulers | K29: 36
A30: 2024 | B30: Region Asia | C30: MA Asia East | D30: Japan | E30: JP | F30: General Purpose Equipment | G30: Articulated Haulers | H30: 330 | I30: AH35+ | J30: Articulated Haulers | K30: 78
A31: 2024 | B31: Region Asia | C31: MA Asia East | D31: Japan | E31: JP | F31: General Purpose Equipment | G31: GPE Crawler Excavators | H31: 310 | I31: EC100<120 | J31: >10T | K31: 12
... A75: 2024 | B75: Region Asia | C75: MA Asia East | D75: Japan | E75: JP | F75: Road Machinery Equipment | G75: Compaction Machines | H75: 390 | I75: VTR-2D8.0<11.3 | J75: Compaction Machines | K75: 0
A76: 2024 | B76: Region Asia | C76: MA Asia East | D76: Malaysia | E76: MY | F76: Compact Equipment | G76: Compact Excavators | H76: CEX | I76: EC1<2 | J76: <6T | K76: 15
A77: 2024 | B77: Region Asia | C77: MA Asia East | D77: Malaysia | E77: MY | F77: Compact Equipment | G77: Compact Excavators | H77: CEX | I77: EC2<3 | J77: <6T | K77: 7
A78: 2024 | B78: Region Asia | C78: MA Asia East | D78: Malaysia | E78: MY | F78: Compact Equipment | G78: Compact Excavators | H78: CEX | I78: EC3<4 | J78: <6T | K78: 54
A79: 2024 | B79: Region Asia | C79: MA Asia East | D79: Malaysia | E79: MY | F79: Compact Equipment | G79: Compact Excavators | H79: CEX | I79: EC4<5 | J79: <6T | K79: 25
A80: 2024 | B80: Region Asia | C80: MA Asia East | D80: Malaysia | E80: MY | F80: Compact Equipment | G80: Compact Excavators | H80: CEX | I80: EC5<6 | J80: <6T | K80: 50
A81: 2024 | B81: Region Asia | C81: MA Asia East | D81: Malaysia | E81: MY | F81: Compact Equipment | G81: Compact Excavators | H81: CEX | I81: EC6<8 | J81: 6<10T | K81: 141
A82: 2024 | B82: Region Asia | C82: MA Asia East | D82: Malaysia | E82: MY | F82: Compact Equipment | G82: Compact Excavators | H82: CEX | I82: EC8<10 | J82: 6<10T | K82: 1
A83: 2024 | B83: Region Asia | C83: MA Asia East | D83: Malaysia | E83: MY | F83: Compact Equipment | G83: Compact Excavators | H83: CEX | I83: EW0<6 | J83: <6T | K83: 2
...

Sheet CRP VOLVO SAL 
A1: Source | B1: Country Grouping | C1: Country | D1: Market Area | E1: Machine Line | F1: Size Class Flag | G1: Brand Code | H1: FID | I1: TM FID | J1: check sap | K1: check 2024
A2: SAL | B2: Algeria | C2: Algeria | D2: # | E2: Articulated Haulers | F2: Not assigned | G2: Volvo | H2: 12 | I2: 0 | J2: =IF(COUNTIFS('source matrix sap'!$B:$B,$B2,'source matrix sap'!$D:$D,$E2)>0,1,0) -> 1 | K2: =IF(COUNTIFS('source matrix 2024'!$B:$B,$B2,'source matrix 2024'!$D:$D,$E2)>0,1,0) -> 0
A3: SAL | B3: Algeria | C3: Algeria | D3: # | E3: GPE Crawler Excavators | F3: >10t | G3: Volvo | H3: 25 | I3: 0 | J3: =IF(COUNTIFS('source matrix sap'!$B:$B,$B3,'source matrix sap'!$D:$D,$E3)>0,1,0) -> 1 | K3: =IF(COUNTIFS('source matrix 2024'!$B:$B,$B3,'source matrix 2024'!$D:$D,$E3)>0,1,0) -> 0
A4: SAL | B4: Argentina | C4: Argentina | D4: # | E4: Articulated Haulers | F4: Not assigned | G4: Volvo | H4: 6 | I4: 0 | J4: =IF(COUNTIFS('source matrix sap'!$B:$B,$B4,'source matrix sap'!$D:$D,$E4)>0,1,0) -> 1 | K4: =IF(COUNTIFS('source matrix 2024'!$B:$B,$B4,'source matrix 2024'!$D:$D,$E4)>0,1,0) -> 1
A5: SAL | B5: Argentina | C5: Argentina | D5: # | E5: Compact Excavators | F5: <6t | G5: Volvo | H5: 6 | I5: 0 | J5: =IF(COUNTIFS('source matrix sap'!$B:$B,$B5,'source matrix sap'!$D:$D,$E5)>0,1,0) -> 1 | K5: =IF(COUNTIFS('source matrix 2024'!$B:$B,$B5,'source matrix 2024'!$D:$D,$E5)>0,1,0) -> 1
A6: SAL | B6: Argentina | C6: Argentina | D6: # | E6: Compact Wheel Loaders | F6: 7<10 | G6: SDLG | H6: 19 | I6: 0 | J6: =IF(COUNTIFS('source matrix sap'!$B:$B,$B6,'source matrix sap'!$D:$D,$E6)>0,1,0) -> 1 | K6: =IF(COUNTIFS('source matrix 2024'!$B:$B,$B6,'source matrix 2024'!$D:$D,$E6)>0,1,0) -> 1
A7: SAL | B7: Argentina | C7: Argentina | D7: # | E7: Compact Wheel Loaders | F7: 7<10 | G7: Volvo | H7: 1 | I7: 0 | J7: =IF(COUNTIFS('source matrix sap'!$B:$B,$B7,'source matrix sap'!$D:$D,$E7)>0,1,0) -> 1 | K7: =IF(COUNTIFS('source matrix 2024'!$B:$B,$B7,'source matrix 2024'!$D:$D,$E7)>0,1,0) -> 1
A8: SAL | B8: Argentina | C8: Argentina | D8: # | E8: Compaction Machines | F8: Not assigned | G8: Volvo | H8: 5 | I8: 0 | J8: =IF(COUNTIFS('source matrix sap'!$B:$B,$B8,'source matrix sap'!$D:$D,$E8)>0,1,0) -> 1 | K8: =IF(COUNTIFS('source matrix 2024'!$B:$B,$B8,'source matrix 2024'!$D:$D,$E8)>0,1,0) -> 1
A9: SAL | B9: Argentina | C9: Argentina | D9: # | E9: GPE Crawler Excavators | F9: >10t | G9: Volvo | H9: 38 | I9: 0 | J9: =IF(COUNTIFS('source matrix sap'!$B:$B,$B9,'source matrix sap'!$D:$D,$E9)>0,1,0) -> 1 | K9: =IF(COUNTIFS('source matrix 2024'!$B:$B,$B9,'source matrix 2024'!$D:$D,$E9)>0,1,0) -> 1
A10: SAL | B10: Argentina | C10: Argentina | D10: # | E10: GPE Wheel Loaders | F10: >12 | G10: SDLG | H10: 60 | I10: 0 | J10: =IF(COUNTIFS('source matrix sap'!$B:$B,$B10,'source matrix sap'!$D:$D,$E10)>0,1,0) -> 1 | K10: =IF(COUNTIFS('source matrix 2024'!$B:$B,$B10,'source matrix 2024'!$D:$D,$E10)>0,1,0) -> 1
A11: SAL | B11: Argentina | C11: Argentina | D11: # | E11: GPE Wheel Loaders | F11: >12 | G11: Volvo | H11: 31 | I11: 0 | J11: =IF(COUNTIFS('source matrix sap'!$B:$B,$B11,'source matrix sap'!$D:$D,$E11)>0,1,0) -> 1 | K11: =IF(COUNTIFS('source matrix 2024'!$B:$B,$B11,'source matrix 2024'!$D:$D,$E11)>0,1,0) -> 1
A12: SAL | B12: Argentina | C12: Argentina | D12: # | E12: Motor Graders | F12: Not assigned | G12: SDLG | H12: 8 | I12: 0 | J12: =IF(COUNTIFS('source matrix sap'!$B:$B,$B12,'source matrix sap'!$D:$D,$E12)>0,1,0) -> 1 | K12: =IF(COUNTIFS('source matrix 2024'!$B:$B,$B12,'source matrix 2024'!$D:$D,$E12)>0,1,0) -> 1
A13: SAL | B13: Australia | C13: Australia | D13: # | E13: Articulated Haulers | F13: Not assigned | G13: Terex Trucks | H13: 25 | I13: 0 | J13: =IF(COUNTIFS('source matrix sap'!$B:$B,$B13,'source matrix sap'!$D:$D,$E13)>0,1,0) -> 1 | K13: =IF(COUNTIFS('source matrix 2024'!$B:$B,$B13,'source matrix 2024'!$D:$D,$E13)>0,1,0) -> 1
... A897: SAL | B897: VietNam | C897: Viet Nam | D897: # | E897: Motor Graders | F897: Not assigned | G897: SDLG | H897: 1 | I897: 0 | J897: =IF(COUNTIFS('source matrix sap'!$B:$B,$B897,'source matrix sap'!$D:$D,$E897)>0,1,0) -> 1 | K897: =IF(COUNTIFS('source matrix 2024'!$B:$B,$B897,'source matrix 2024'!$D:$D,$E897)>0,1,0) -> 1

Sheet TMC VOLVO SAL Preparation
A1: Country Grouping | C1: Country | D1: Region | E1: Machine Line | G1: Size Class Flag | H1: Brand Code | I1: Reporter Flag | J1: Pri/Sec | K1: Source | L1: FID | M1: MS (%) | N1: TM | O1: VCE FID | P1: TM Non-VCE
A2: GAE | B2: UAE | C2: UAE | D2: Region International | E2: 300 | F2: Compact Excavators | G2: 6<10T | H2: Volvo | I2: Y | J2: # | K2: SAL | L2: 2 | M2: 0 | N2: 0
A3: GAE | B3: UAE | C3: UAE | D3: Region International | E3: 300 | F3: Compact Excavators | G3: <6T | H3: Volvo | I3: Y | J3: # | K3: SAL | L3: 1 | M3: 0 | N3: 0
A4: GAE | B4: UAE | C4: UAE | D4: Region International | E4: 310 | F4: GPE Crawler Excavators | G4: >10T | H4: SDLG | I4: Y | J4: # | K4: SAL | L4: 5 | M4: 0 | N4: 0
A5: GAE | B5: UAE | C5: UAE | D5: Region International | E5: 310 | F5: GPE Crawler Excavators | G5: >10T | H5: Volvo | I5: Y | J5: # | K5: SAL | L5: 50 | M5: 0 | N5: 0
A6: GAE | B6: UAE | C6: UAE | D6: Region International | E6: 320 | F6: GPE Wheel Excavators | G6: >11T | H6: Volvo | I6: Y | J6: # | K6: SAL | L6: 28 | M6: 0 | N6: 0
A7: GAE | B7: UAE | C7: UAE | D7: Region International | E7: 330 | F7: Articulated Haulers | G7: # | H7: Volvo | I7: Y | J7: # | K7: SAL | L7: 129 | M7: 0 | N7: 0
A8: GAE | B8: UAE | C8: UAE | D8: Region International | E8: 350 | F8: Compact Wheel Loaders | G8: 7<10 | H8: SDLG | I8: Y | J8: # | K8: SAL | L8: 1 | M8: 0 | N8: 0
A9: GAE | B9: UAE | C9: UAE | D9: Region International | E9: 360 | F9: GPE Wheel Loaders | G9: >12 | H9: SDLG | I9: Y | J9: # | K9: SAL | L9: 101 | M9: 0 | N9: 0
A10: GAE | B10: UAE | C10: UAE | D10: Region International | E10: 360 | F10: GPE Wheel Loaders | G10: >12 | H10: Volvo | I10: Y | J10: # | K10: SAL | L10: 59 | M10: 0 | N10: 0
A11: GAE | B11: UAE | C11: UAE | D11: Region International | E11: 380 | F11: Motor Graders | G11: # | H11: SDLG | I11: Y | J11: # | K11: SAL | L11: 8 | M11: 0 | N11: 0
A12: GAE | B12: UAE | C12: UAE | D12: Region International | E12: 390 | F12: Compaction Machines | G12: # | H12: Volvo | I12: Y | J12: # | K12: SAL | L12: 7 | M12: 0 | N12: 0
A13: GAE | B13: UAE | C13: UAE | D13: Region International | E13: 400 | F13: Paving Machines | G13: # | H13: ABG | I13: Y | J13: # | K13: SAL | L13: 3 | M13: 0 | N13: 0
... A493: GZA | B493: South Africa | C493: South Africa | D493: Region International | E493: 360 | F493: GPE Wheel Loaders | G493: >12 | H493: Volvo | I493: Y | J493: # | K493: SAL | L493: 103 | M493: 0 | N493: 0

Sheet VOLVO 2024
A1: calendar | B1: region | C1: market | D1: country | E1: machine | F1: machine_line | G1: size_class | H1: brand_owner_code | I1: brand_owner | J1: brand | K1: brand_nationality | L1: source | M1: fid
A2: 2024 | B2: Region Asia | C2: MA Asia East | D2: Japan | E2: CEX | F2: Compact Excavators | G2: Midi | H2: VCE | I2: Volvo CE | J2: Volvo | K2: Sweden | L2: SAL | M2: 2
A3: 2024 | B3: Region Asia | C3: MA Asia East | D3: Japan | E3: CEX | F3: Compact Excavators | G3: Mini | H3: VCE | I3: Volvo CE | J3: Volvo | K3: Sweden | L3: SAL | M3: 9
A4: 2024 | B4: Region Asia | C4: MA Asia East | D4: Japan | E4: 310 | F4: GPE Crawler Excavators | G4: >10T | H4: VCE | I4: Volvo CE | J4: Volvo | K4: Sweden | L4: SAL | M4: 16
A5: 2024 | B5: Region Asia | C5: MA Asia East | D5: Japan | E5: 320 | F5: GPE Wheel Excavators | G5: >11T | H5: VCE | I5: Volvo CE | J5: Volvo | K5: Sweden | L5: SAL | M5: 5
A6: 2024 | B6: Region Asia | C6: MA Asia East | D6: Japan | E6: 330 | F6: Articulated Haulers | G6: Articulated Haulers | H6: VCE | I6: Volvo CE | J6: Volvo | K6: Sweden | L6: SAL | M6: 56
A7: 2024 | B7: Region Asia | C7: MA Asia East | D7: Japan | E7: 350 | F7: Compact Wheel Loaders | G7: 7<10 | H7: VCE | I7: Volvo CE | J7: Volvo | K7: Sweden | L7: SAL | M7: 10
A8: 2024 | B8: Region Asia | C8: MA Asia East | D8: Japan | E8: 360 | F8: GPE Wheel Loaders | G8: >12 | H8: VCE | I8: Volvo CE | J8: Volvo | K8: Sweden | L8: SAL | M8: 5
A9: 2024 | B9: Region Asia | C9: MA Asia East | D9: Malaysia | E9: CEX | F9: Compact Excavators | G9: Midi | H9: VCE | I9: Volvo CE | J9: SDLG | K9: China | L9: SAL | M9: 10
A10: 2024 | B10: Region Asia | C10: MA Asia East | D10: Malaysia | E10: CEX | F10: Compact Excavators | G10: Mini | H10: VCE | I10: Volvo CE | J10: SDLG | K10: China | L10: SAL | M10: 6
A11: 2024 | B11: Region Asia | C11: MA Asia East | D11: Malaysia | E11: 310 | F11: GPE Crawler Excavators | G11: >10T | H11: VCE | I11: Volvo CE | J11: SDLG | K11: China | L11: SAL | M11: 50
A12: 2024 | B12: Region Asia | C12: MA Asia East | D12: Malaysia | E12: 310 | F12: GPE Crawler Excavators | G12: >10T | H12: VCE | I12: Volvo CE | J12: Volvo | K12: Sweden | L12: SAL | M12: 75
A13: 2024 | B13: Region Asia | C13: MA Asia East | D13: Malaysia | E13: 350 | F13: Compact Wheel Loaders | G13: 7<10 | H13: VCE | I13: Volvo CE | J13: SDLG | K13: China | L13: SAL | M13: 2
A14: 2024 | B14: Region Asia | C14: MA Asia East | D14: Malaysia | E14: 360 | F14: GPE Wheel Loaders | G14: >12 | H14: VCE | I14: Volvo CE | J14: SDLG | K14: China | L14: SAL | M14: 37
A15: 2024 | B15: Region Asia | C15: MA Asia East | D15: Malaysia | E15: 360 | F15: GPE Wheel Loaders | G15: >12 | H15: VCE | I15: Volvo CE | J15: Volvo | K15: Sweden | L15: SAL | M15: 4
A16: 2024 | B16: Region Asia | C16: MA Asia East | D16: Philippines | E16: CEX | F16: Compact Excavators | G16: Midi | H16: VCE | I16: Volvo CE | J16: SDLG | K16: China | L16: SAL | M16: 30
A17: 2024 | B17: Region Asia | C17: MA Asia East | D17: Philippines | E17: CEX | F17: Compact Excavators | G17: Mini | H17: VCE | I17: Volvo CE | J17: SDLG | K17: China | L17: SAL | M17: 13
A18: 2024 | B18: Region Asia | C18: MA Asia East | D18: Philippines | E18: CEX | F18: Compact Excavators | G18: Mini | H18: VCE | I18: Volvo CE | J18: Volvo | K18: Sweden | L18: SAL | M18: 5
A19: 2024 | B19: Region Asia | C19: MA Asia East | D19: Philippines | E19: 310 | F19: GPE Crawler Excavators | G19: >10T | H19: VCE | I19: Volvo CE | J19: SDLG | K19: China | L19: SAL | M19: 178
A20: 2024 | B20: Region Asia | C20: MA Asia East | D20: Philippines | E20: 310 | F20: GPE Crawler Excavators | G20: >10T | H20: VCE | I20: Volvo CE | J20: Volvo | K20: Sweden | L20: SAL | M20: 159
A21: 2024 | B21: Region Asia | C21: MA Asia East | D21: Philippines | E21: 320 | F21: GPE Wheel Excavators | G21: >11T | H21: VCE | I21: Volvo CE | J21: SDLG | K21: China | L21: SAL | M21: 30
A22: 2024 | B22: Region Asia | C22: MA Asia East | D22: Philippines | E22: 320 | F22: GPE Wheel Excavators | G22: >11T | H22: VCE | I22: Volvo CE | J22: Volvo | K22: Sweden | L22: SAL | M22: 68
A23: 2024 | B23: Region Asia | C23: MA Asia East | D23: Philippines | E23: 330 | F23: Articulated Haulers | G23: Articulated Haulers | H23: VCE | I23: Volvo CE | J23: Volvo | K23: Sweden | L23: SAL | M23: 7
A24: 2024 | B24: Region Asia | C24: MA Asia East | D24: Philippines | E24: 350 | F24: Compact Wheel Loaders | G24: 7<10 | H24: VCE | I24: Volvo CE | J24: SDLG | K24: China | L24: SAL | M24: 4
A25: 2024 | B25: Region Asia | C25: MA Asia East | D25: Philippines | E25: 360 | F25: GPE Wheel Loaders | G25: >12 | H25: VCE | I25: Volvo CE | J25: SDLG | K25: China | L25: SAL | M25: 92
A26: 2024 | B26: Region Asia | C26: MA Asia East | D26: Philippines | E26: 360 | F26: GPE Wheel Loaders | G26: >12 | H26: VCE | I26: Volvo CE | J26: Volvo | K26: Sweden | L26: SAL | M26: 4
A27: 2024 | B27: Region Asia | C27: MA Asia East | D27: Singapore | E27: CEX | F27: Compact Excavators | G27: Mini | H27: VCE | I27: Volvo CE | J27: Volvo | K27: Sweden | L27: SAL | M27: 1
A28: 2024 | B28: Region Asia | C28: MA Asia East | D28: Singapore | E28: 310 | F28: GPE Crawler Excavators | G28: >10T | H28: VCE | I28: Volvo CE | J28: Volvo | K28: Sweden | L28: SAL | M28: 28
A29: 2024 | B29: Region Asia | C29: MA Asia East | D29: Singapore | E29: 330 | F29: Articulated Haulers | G29: Articulated Haulers | H29: VCE | I29: Volvo CE | J29: Volvo | K29: Sweden | L29: SAL | M29: 40
A30: 2024 | B30: Region Asia | C30: MA Asia East | D30: Singapore | E30: 360 | F30: GPE Wheel Loaders | G30: >12 | H30: VCE | I30: Volvo CE | J30: Volvo | K30: Sweden | L30: SAL | M30: 10
A31: 2024 | B31: Region Asia | C31: MA Asia East | D31: Taiwan | E31: CEX | F31: Compact Excavators | G31: Midi | H31: VCE | I31: Volvo CE | J31: SDLG | K31: China | L31: SAL | M31: 1
A32: 2024 | B32: Region Asia | C32: MA Asia East | D32: Taiwan | E32: CEX | F32: Compact Excavators | G32: Midi | H32: VCE | I32: Volvo CE | J32: Volvo | K32: Sweden | L32: SAL | M32: 1
A33: 2024 | B33: Region Asia | C33: MA Asia East | D33: Taiwan | E33: CEX | F33: Compact Excavators | G33: Mini | H33: VCE | I33: Volvo CE | J33: SDLG | K33: China | L33: SAL | M33: 1
A34: 2024 | B34: Region Asia | C34: MA Asia East | D34: Taiwan | E34: 310 | F34: GPE Crawler Excavators | G34: >10T | H34: VCE | I34: Volvo CE | J34: SDLG | K34: China | L34: SAL | M34: 6
A35: 2024 | B35: Region Asia | C35: MA Asia East | D35: Taiwan | E35: 310 | F35: GPE Crawler Excavators | G35: >10T | H35: VCE | I35: Volvo CE | J35: Volvo | K35: Sweden | L35: SAL | M35: 40
A36: 2024 | B36: Region Asia | C36: MA Asia East | D36: Taiwan | E36: 330 | F36: Articulated Haulers | G36: Articulated Haulers | H36: VCE | I36: Volvo CE | J36: Volvo | K36: Sweden | L36: SAL | M36: 25
A37: 2024 | B37: Region Asia | C37: MA Asia East | D37: Taiwan | E37: 350 | F37: Compact Wheel Loaders | G37: 7<10 | H37: VCE | I37: Volvo CE | J37: SDLG | K37: China | L37: SAL | M37: 1
A38: 2024 | B38: Region Asia | C38: MA Asia East | D38: Taiwan | E38: 360 | F38: GPE Wheel Loaders | G38: >12 | H38: VCE | I38: Volvo CE | J38: SDLG | K38: China | L38: SAL | M38: 11
A39: 2024 | B39: Region Asia | C39: MA Asia East | D39: Taiwan | E39: 360 | F39: GPE Wheel Loaders | G39: >12 | H39: VCE | I39: Volvo CE | J39: Volvo | K39: Sweden | L39: SAL | M39: 2
A40: 2024 | B40: Region Asia | C40: MA Asia West | D40: Cambodia | E40: 350 | F40: Compact Wheel Loaders | G40: 7<10 | H40: VCE | I40: Volvo CE | J40: SDLG | K40: China | L40: SAL | M40: 2
...

Sheet TMC OTH
A1: Calendar Year | B1: Source | D1: Country | E1: Country Grouping | F1: Region | G1: Machine Line Name | H1: Size Class Flag | I1: Brand Name | J1: FID | K1: MS (%)
A2: 2024 | B2: CLF | C2: Chile OTH | D2: CL | E2: # | F2: Not Assigned | G2: Articulated Haulers | H2: # | I2: Bell | J2: 5 | K2: 0
A3: 2024 | B3: CLF | C3: Chile OTH | D3: CL | E3: # | F3: Not Assigned | G3: Articulated Haulers | H3: # | I3: Caterpillar | J3: 3 | K3: 0
A4: 2024 | B4: CLF | C4: Chile OTH | D4: CL | E4: # | F4: Not Assigned | G4: Articulated Haulers | H4: # | I4: Develon | J4: 2 | K4: 0
A5: 2024 | B5: CLF | C5: Chile OTH | D5: CL | E5: # | F5: Not Assigned | G5: Articulated Haulers | H5: # | I5: Volvo | J5: 14 | K5: 0
A6: 2024 | B6: CLF | C6: Chile OTH | D6: CL | E6: # | F6: Not Assigned | G6: Backhoe Loaders | H6: # | I6: Bobcat | J6: 14 | K6: 0
A7: 2024 | B7: CLF | C7: Chile OTH | D7: CL | E7: # | F7: Not Assigned | G7: Backhoe Loaders | H7: # | I7: Bull | J7: 3 | K7: 0
A8: 2024 | B8: CLF | C8: Chile OTH | D8: CL | E8: # | F8: Not Assigned | G8: Backhoe Loaders | H8: # | I8: Case | J8: 37 | K8: 0
A9: 2024 | B9: CLF | C9: Chile OTH | D9: CL | E9: # | F9: Not Assigned | G9: Backhoe Loaders | H9: # | I9: Caterpillar | J9: 283 | K9: 0
A10: 2024 | B10: CLF | C10: Chile OTH | D10: CL | E10: # | F10: Not Assigned | G10: Backhoe Loaders | H10: # | I10: Cukurova | J10: 5 | K10: 0
A11: 2024 | B11: CLF | C11: Chile OTH | D11: CL | E11: # | F11: Not Assigned | G11: Backhoe Loaders | H11: # | I11: Deere | J11: 162 | K11: 0
A12: 2024 | B12: CLF | C12: Chile OTH | D12: CL | E12: # | F12: Not Assigned | G12: Backhoe Loaders | H12: # | I12: Develon | J12: 22 | K12: 0
A13: 2024 | B13: CLF | C13: Chile OTH | D13: CL | E13: # | F13: Not Assigned | G13: Backhoe Loaders | H13: # | I13: Hengwang | J13: 1 | K13: 0
... A4396: 2024 | B4396: PIN | C4396: Market PINS | D4396: UY | E4396: # | F4396: Not Assigned | G4396: Wheeled Excavators | H4396: >11T | I4396: Liugong | J4396: 1 | K4396: 0

Sheet TMC OTH Preparation
A1: Country Grouping | C1: Country | D1: Region | E1: Machine Line | F1: Machine Line | H1: Size Class Flag | I1: Brand Code | K1: Reporter Flag | L1: Pri/Sec | M1: Source | N1: FID | O1: MS (%) | P1: TM | Q1: VCE FID | R1: TM Non-VCE | S1: CHECK 2024
A2: GAE | B2: UAE | C2: UAE | D2: Region International | E2: 330 | F2: Articulated Haulers | H2: # | I2: Caterpillar Inc | J2: =_xlfn.XLOOKUP(UPPER(TRIM(I2)),Sheet19!$A:$A,Sheet19!$B:$B,"") | K2: Y | L2: P | M2: DES | N2: 18 | O2: 0 | P2: 0 | S2: =IF(COUNTIFS('OTH Preparationet 2024'!$D:$D,$C2,'OTH Preparationet 2024'!$H:$H,$F2,'OTH Preparationet 2024'!$M:$M,$H2,'OTH Preparationet 2024'!$L:$L,$J2,'OTH Preparationet 2024'!$Q:$Q,"")>0,1,0) -> 0
A3: GAE | B3: UAE | C3: UAE | D3: Region International | E3: 330 | F3: Articulated Haulers | H3: # | I3: Develon | J3: =_xlfn.XLOOKUP(UPPER(TRIM(I3)),Sheet19!$A:$A,Sheet19!$B:$B,"") -> DOO | K3: Y | L3: P | M3: DES | N3: 4 | O3: 0 | P3: 0 | S3: =IF(COUNTIFS('OTH Preparationet 2024'!$D:$D,$C3,'OTH Preparationet 2024'!$H:$H,$F3,'OTH Preparationet 2024'!$M:$M,$H3,'OTH Preparationet 2024'!$L:$L,$J3,'OTH Preparationet 2024'!$Q:$Q,"")>0,1,0) -> 0
A4: GAE | B4: UAE | C4: UAE | D4: Region International | E4: 330 | F4: Articulated Haulers | H4: # | I4: Komatsu | J4: =_xlfn.XLOOKUP(UPPER(TRIM(I4)),Sheet19!$A:$A,Sheet19!$B:$B,"") -> KOM | K4: Y | L4: P | M4: DES | N4: 80 | O4: 0 | P4: 0 | S4: =IF(COUNTIFS('OTH Preparationet 2024'!$D:$D,$C4,'OTH Preparationet 2024'!$H:$H,$F4,'OTH Preparationet 2024'!$M:$M,$H4,'OTH Preparationet 2024'!$L:$L,$J4,'OTH Preparationet 2024'!$Q:$Q,"")>0,1,0) -> 0
A5: GAE | B5: UAE | C5: UAE | D5: Region International | E5: 330 | F5: Articulated Haulers | H5: # | I5: Volvo | J5: =_xlfn.XLOOKUP(UPPER(TRIM(I5)),Sheet19!$A:$A,Sheet19!$B:$B,"") -> VCE | K5: Y | L5: P | M5: DES | N5: 129 | O5: 0 | P5: 0 | S5: =IF(COUNTIFS('OTH Preparationet 2024'!$D:$D,$C5,'OTH Preparationet 2024'!$H:$H,$F5,'OTH Preparationet 2024'!$M:$M,$H5,'OTH Preparationet 2024'!$L:$L,$J5,'OTH Preparationet 2024'!$Q:$Q,"")>0,1,0) -> 0
A6: GAE | B6: UAE | C6: UAE | D6: Region International | E6: 340 | F6: Rigid Haulers | H6: # | I6: Komatsu | J6: =_xlfn.XLOOKUP(UPPER(TRIM(I6)),Sheet19!$A:$A,Sheet19!$B:$B,"") -> KOM | K6: Y | L6: P | M6: DES | N6: 106 | O6: 0 | P6: 0 | S6: =IF(COUNTIFS('OTH Preparationet 2024'!$D:$D,$C6,'OTH Preparationet 2024'!$H:$H,$F6,'OTH Preparationet 2024'!$M:$M,$H6,'OTH Preparationet 2024'!$L:$L,$J6,'OTH Preparationet 2024'!$Q:$Q,"")>0,1,0) -> 0
A7: GAE | B7: UAE | C7: UAE | D7: Region International | E7: 340 | F7: Rigid Haulers | H7: # | I7: Sany | J7: =_xlfn.XLOOKUP(UPPER(TRIM(I7)),Sheet19!$A:$A,Sheet19!$B:$B,"") -> SNY | K7: Y | L7: P | M7: DES | N7: 18 | O7: 0 | P7: 0 | S7: =IF(COUNTIFS('OTH Preparationet 2024'!$D:$D,$C7,'OTH Preparationet 2024'!$H:$H,$F7,'OTH Preparationet 2024'!$M:$M,$H7,'OTH Preparationet 2024'!$L:$L,$J7,'OTH Preparationet 2024'!$Q:$Q,"")>0,1,0) -> 0
A8: GAE | B8: UAE | C8: UAE | D8: Region International | E8: CEX | F8: Compact Excavators | H8: <10T | I8: Bobcat | J8: =_xlfn.XLOOKUP(UPPER(TRIM(I8)),Sheet19!$A:$A,Sheet19!$B:$B,"") -> BOB | K8: Y | L8: P | M8: DES | N8: 13 | O8: 0 | P8: 0 | S8: =IF(COUNTIFS('OTH Preparationet 2024'!$D:$D,$C8,'OTH Preparationet 2024'!$H:$H,$F8,'OTH Preparationet 2024'!$M:$M,$H8,'OTH Preparationet 2024'!$L:$L,$J8,'OTH Preparationet 2024'!$Q:$Q,"")>0,1,0) -> 0
A9: GAE | B9: UAE | C9: UAE | D9: Region International | E9: CEX | F9: Compact Excavators | H9: <10T | I9: Caterpillar Inc | J9: =_xlfn.XLOOKUP(UPPER(TRIM(I9)),Sheet19!$A:$A,Sheet19!$B:$B,"") | K9: Y | L9: P | M9: DES | N9: 31 | O9: 0 | P9: 0 | S9: =IF(COUNTIFS('OTH Preparationet 2024'!$D:$D,$C9,'OTH Preparationet 2024'!$H:$H,$F9,'OTH Preparationet 2024'!$M:$M,$H9,'OTH Preparationet 2024'!$L:$L,$J9,'OTH Preparationet 2024'!$Q:$Q,"")>0,1,0) -> 0
A10: GAE | B10: UAE | C10: UAE | D10: Region International | E10: CEX | F10: Compact Excavators | H10: <10T | I10: Develon | J10: =_xlfn.XLOOKUP(UPPER(TRIM(I10)),Sheet19!$A:$A,Sheet19!$B:$B,"") -> DOO | K10: Y | L10: P | M10: DES | N10: 3 | O10: 0 | P10: 0 | S10: =IF(COUNTIFS('OTH Preparationet 2024'!$D:$D,$C10,'OTH Preparationet 2024'!$H:$H,$F10,'OTH Preparationet 2024'!$M:$M,$H10,'OTH Preparationet 2024'!$L:$L,$J10,'OTH Preparationet 2024'!$Q:$Q,"")>0,1,0) -> 0
A11: GAE | B11: UAE | C11: UAE | D11: Region International | E11: CEX | F11: Compact Excavators | H11: <10T | I11: Hitachi | J11: =_xlfn.XLOOKUP(UPPER(TRIM(I11)),Sheet19!$A:$A,Sheet19!$B:$B,"") -> HIT | K11: Y | L11: P | M11: DES | N11: 34 | O11: 0 | P11: 0 | S11: =IF(COUNTIFS('OTH Preparationet 2024'!$D:$D,$C11,'OTH Preparationet 2024'!$H:$H,$F11,'OTH Preparationet 2024'!$M:$M,$H11,'OTH Preparationet 2024'!$L:$L,$J11,'OTH Preparationet 2024'!$Q:$Q,"")>0,1,0) -> 0
A12: GAE | B12: UAE | C12: UAE | D12: Region International | E12: CEX | F12: Compact Excavators | H12: <10T | I12: JCB | J12: =_xlfn.XLOOKUP(UPPER(TRIM(I12)),Sheet19!$A:$A,Sheet19!$B:$B,"") -> JCB | K12: Y | L12: P | M12: DES | N12: 10 | O12: 0 | P12: 0 | S12: =IF(COUNTIFS('OTH Preparationet 2024'!$D:$D,$C12,'OTH Preparationet 2024'!$H:$H,$F12,'OTH Preparationet 2024'!$M:$M,$H12,'OTH Preparationet 2024'!$L:$L,$J12,'OTH Preparationet 2024'!$Q:$Q,"")>0,1,0) -> 0
A13: GAE | B13: UAE | C13: UAE | D13: Region International | E13: CEX | F13: Compact Excavators | H13: <10T | I13: Kobelco | J13: =_xlfn.XLOOKUP(UPPER(TRIM(I13)),Sheet19!$A:$A,Sheet19!$B:$B,"") -> KOB | K13: Y | L13: P | M13: DES | N13: 25 | O13: 0 | P13: 0 | S13: =IF(COUNTIFS('OTH Preparationet 2024'!$D:$D,$C13,'OTH Preparationet 2024'!$H:$H,$F13,'OTH Preparationet 2024'!$M:$M,$H13,'OTH Preparationet 2024'!$L:$L,$J13,'OTH Preparationet 2024'!$Q:$Q,"")>0,1,0) -> 0
... A29: GAE | B29: UAE | C29: UAE | D29: Region International | E29: GEC | F29: GPE Excavators Crawled | H29: >10T | I29: Liugong | J29: =_xlfn.XLOOKUP(UPPER(TRIM(I29)),Sheet19!$A:$A,Sheet19!$B:$B,"") -> LIU | K29: Y | L29: P | M29: DES | N29: 53 | O29: 0 | P29: 0 | S29: =IF(COUNTIFS('OTH Preparationet 2024'!$D:$D,$C29,'OTH Preparationet 2024'!$H:$H,$F29,'OTH Preparationet 2024'!$M:$M,$H29,'OTH Preparationet 2024'!$L:$L,$J29,'OTH Preparationet 2024'!$Q:$Q,"")>0,1,0) -> 0
A30: GAE | B30: UAE | C30: UAE | D30: Region International | E30: GEC | F30: Crawler Excavators | H30: >10T | I30: Lonking | J30: =_xlfn.XLOOKUP(UPPER(TRIM(I30)),Sheet19!$A:$A,Sheet19!$B:$B,"") -> LON | L30: P | M30: DES | N30: 10 | O30: 0 | P30: 0 | S30: =IF(COUNTIFS('OTH Preparationet 2024'!$D:$D,$C30,'OTH Preparationet 2024'!$H:$H,$F30,'OTH Preparationet 2024'!$M:$M,$H30,'OTH Preparationet 2024'!$L:$L,$J30,'OTH Preparationet 2024'!$Q:$Q,"")>0,1,0) -> 0
A31: GAE | B31: UAE | C31: UAE | D31: Region International | E31: GEC | F31: GPE Excavators Crawled | H31: >10T | I31: Sany | J31: =_xlfn.XLOOKUP(UPPER(TRIM(I31)),Sheet19!$A:$A,Sheet19!$B:$B,"") -> SNY | K31: Y | L31: P | M31: DES | N31: 212 | O31: 0 | P31: 0 | S31: =IF(COUNTIFS('OTH Preparationet 2024'!$D:$D,$C31,'OTH Preparationet 2024'!$H:$H,$F31,'OTH Preparationet 2024'!$M:$M,$H31,'OTH Preparationet 2024'!$L:$L,$J31,'OTH Preparationet 2024'!$Q:$Q,"")>0,1,0) -> 0
A32: GAE | B32: UAE | C32: UAE | D32: Region International | E32: GEC | F32: GPE Excavators Crawled | H32: >10T | I32: SDLG | J32: =_xlfn.XLOOKUP(UPPER(TRIM(I32)),Sheet19!$A:$A,Sheet19!$B:$B,"") -> LIN | K32: Y | L32: P | M32: DES | N32: 1 | O32: 0 | P32: 0 | S32: =IF(COUNTIFS('OTH Preparationet 2024'!$D:$D,$C32,'OTH Preparationet 2024'!$H:$H,$F32,'OTH Preparationet 2024'!$M:$M,$H32,'OTH Preparationet 2024'!$L:$L,$J32,'OTH Preparationet 2024'!$Q:$Q,"")>0,1,0) -> 0
A33: GAE | B33: UAE | C33: UAE | D33: Region International | E33: GEC | F33: GPE Excavators Crawled | H33: >10T | I33: Sunward | J33: =_xlfn.XLOOKUP(UPPER(TRIM(I33)),Sheet19!$A:$A,Sheet19!$B:$B,"") -> SUN | K33: Y | L33: P | M33: DES | N33: 53 | O33: 0 | P33: 0 | S33: =IF(COUNTIFS('OTH Preparationet 2024'!$D:$D,$C33,'OTH Preparationet 2024'!$H:$H,$F33,'OTH Preparationet 2024'!$M:$M,$H33,'OTH Preparationet 2024'!$L:$L,$J33,'OTH Preparationet 2024'!$Q:$Q,"")>0,1,0) -> 0
A34: GAE | B34: UAE | C34: UAE | D34: Region International | E34: GEC | F34: GPE Excavators Crawled | H34: >10T | I34: Volvo | J34: =_xlfn.XLOOKUP(UPPER(TRIM(I34)),Sheet19!$A:$A,Sheet19!$B:$B,"") -> VCE | K34: Y | L34: P | M34: DES | N34: 50 | O34: 0 | P34: 0 | S34: =IF(COUNTIFS('OTH Preparationet 2024'!$D:$D,$C34,'OTH Preparationet 2024'!$H:$H,$F34,'OTH Preparationet 2024'!$M:$M,$H34,'OTH Preparationet 2024'!$L:$L,$J34,'OTH Preparationet 2024'!$Q:$Q,"")>0,1,0) -> 0
A35: GAE | B35: UAE | C35: UAE | D35: Region International | E35: GEC | F35: GPE Excavators Crawled | H35: >10T | I35: XCMG | J35: =_xlfn.XLOOKUP(UPPER(TRIM(I35)),Sheet19!$A:$A,Sheet19!$B:$B,"") -> XCM | K35: Y | L35: P | M35: DES | N35: 212 | O35: 0 | P35: 0 | S35: =IF(COUNTIFS('OTH Preparationet 2024'!$D:$D,$C35,'OTH Preparationet 2024'!$H:$H,$F35,'OTH Preparationet 2024'!$M:$M,$H35,'OTH Preparationet 2024'!$L:$L,$J35,'OTH Preparationet 2024'!$Q:$Q,"")>0,1,0) -> 0
A36: GAE | B36: UAE | C36: UAE | D36: Region International | E36: GEC | F36: GPE Excavators Crawled | H36: >10T | I36: Zoomlion | J36: =_xlfn.XLOOKUP(UPPER(TRIM(I36)),Sheet19!$A:$A,Sheet19!$B:$B,"") -> ZOO | K36: Y | L36: P | M36: DES | N36: 212 | O36: 0 | P36: 0 | S36: =IF(COUNTIFS('OTH Preparationet 2024'!$D:$D,$C36,'OTH Preparationet 2024'!$H:$H,$F36,'OTH Preparationet 2024'!$M:$M,$H36,'OTH Preparationet 2024'!$L:$L,$J36,'OTH Preparationet 2024'!$Q:$Q,"")>0,1,0) -> 0
A37: GAE | B37: UAE | C37: UAE | D37: Region International | E37: GEW | F37: GPE Excavators Wheeled | H37: >11T | I37: Caterpillar Inc | J37: =_xlfn.XLOOKUP(UPPER(TRIM(I37)),Sheet19!$A:$A,Sheet19!$B:$B,"") | K37: Y | L37: P | M37: DES | N37: 22 | O37: 0 | P37: 0 | S37: =IF(COUNTIFS('OTH Preparationet 2024'!$D:$D,$C37,'OTH Preparationet 2024'!$H:$H,$F37,'OTH Preparationet 2024'!$M:$M,$H37,'OTH Preparationet 2024'!$L:$L,$J37,'OTH Preparationet 2024'!$Q:$Q,"")>0,1,0) -> 0
A38: GAE | B38: UAE | C38: UAE | D38: Region International | E38: GEW | F38: GPE Excavators Wheeled | H38: >11T | I38: Develon | J38: =_xlfn.XLOOKUP(UPPER(TRIM(I38)),Sheet19!$A:$A,Sheet19!$B:$B,"") -> DOO | K38: Y | L38: P | M38: DES | N38: 22 | O38: 0 | P38: 0 | S38: =IF(COUNTIFS('OTH Preparationet 2024'!$D:$D,$C38,'OTH Preparationet 2024'!$H:$H,$F38,'OTH Preparationet 2024'!$M:$M,$H38,'OTH Preparationet 2024'!$L:$L,$J38,'OTH Preparationet 2024'!$Q:$Q,"")>0,1,0) -> 0
A39: GAE | B39: UAE | C39: UAE | D39: Region International | E39: GEW | F39: GPE Excavators Wheeled | H39: >11T | I39: Hitachi | J39: =_xlfn.XLOOKUP(UPPER(TRIM(I39)),Sheet19!$A:$A,Sheet19!$B:$B,"") -> HIT | K39: Y | L39: P | M39: DES | N39: 16 | O39: 0 | P39: 0 | S39: =IF(COUNTIFS('OTH Preparationet 2024'!$D:$D,$C39,'OTH Preparationet 2024'!$H:$H,$F39,'OTH Preparationet 2024'!$M:$M,$H39,'OTH Preparationet 2024'!$L:$L,$J39,'OTH Preparationet 2024'!$Q:$Q,"")>0,1,0) -> 0
A40: GAE | B40: UAE | C40: UAE | D40: Region International | E40: GEW | F40: GPE Excavators Wheeled | H40: >11T | I40: Hyundai | J40: =_xlfn.XLOOKUP(UPPER(TRIM(I40)),Sheet19!$A:$A,Sheet19!$B:$B,"") -> HYU | K40: Y | L40: P | M40: DES | N40: 30 | O40: 0 | P40: 0 | S40: =IF(COUNTIFS('OTH Preparationet 2024'!$D:$D,$C40,'OTH Preparationet 2024'!$H:$H,$F40,'OTH Preparationet 2024'!$M:$M,$H40,'OTH Preparationet 2024'!$L:$L,$J40,'OTH Preparationet 2024'!$Q:$Q,"")>0,1,0) -> 0
A41: GAE | B41: UAE | C41: UAE | D41: Region International | E41: GEW | F41: GPE Excavators Wheeled | H41: >11T | I41: JCB | J41: =_xlfn.XLOOKUP(UPPER(TRIM(I41)),Sheet19!$A:$A,Sheet19!$B:$B,"") -> JCB | K41: Y | L41: P | M41: DES | N41: 22 | O41: 0 | P41: 0 | S41: =IF(COUNTIFS('OTH Preparationet 2024'!$D:$D,$C41,'OTH Preparationet 2024'!$H:$H,$F41,'OTH Preparationet 2024'!$M:$M,$H41,'OTH Preparationet 2024'!$L:$L,$J41,'OTH Preparationet 2024'!$Q:$Q,"")>0,1,0) -> 0
A42: GAE | B42: UAE | C42: UAE | D42: Region International | E42: GEW | F42: GPE Excavators Wheeled | H42: >11T | I42: Liugong | J42: =_xlfn.XLOOKUP(UPPER(TRIM(I42)),Sheet19!$A:$A,Sheet19!$B:$B,"") -> LIU | K42: Y | L42: P | M42: DES | N42: 5 | O42: 0 | P42: 0 | S42: =IF(COUNTIFS('OTH Preparationet 2024'!$D:$D,$C42,'OTH Preparationet 2024'!$H:$H,$F42,'OTH Preparationet 2024'!$M:$M,$H42,'OTH Preparationet 2024'!$L:$L,$J42,'OTH Preparationet 2024'!$Q:$Q,"")>0,1,0) -> 0
... A45: GAE | B45: UAE | C45: UAE | D45: Region International | E45: GEW | F45: GPE Excavators Wheeled | H45: >11T | I45: XCMG | J45: =_xlfn.XLOOKUP(UPPER(TRIM(I45)),Sheet19!$A:$A,Sheet19!$B:$B,"") -> XCM | K45: Y | L45: P | M45: DES | N45: 16 | O45: 0 | P45: 0 | S45: =IF(COUNTIFS('OTH Preparationet 2024'!$D:$D,$C45,'OTH Preparationet 2024'!$H:$H,$F45,'OTH Preparationet 2024'!$M:$M,$H45,'OTH Preparationet 2024'!$L:$L,$J45,'OTH Preparationet 2024'!$Q:$Q,"")>0,1,0) -> 0
A46: GAE | B46: UAE | C46: UAE | D46: Region International | E46: GEW | F46: Wheeled Excavators | H46: >11T | I46: Zoomlion | J46: =_xlfn.XLOOKUP(UPPER(TRIM(I46)),Sheet19!$A:$A,Sheet19!$B:$B,"") -> ZOO | L46: P | M46: DES | N46: 10 | O46: 0 | P46: 0 | S46: =IF(COUNTIFS('OTH Preparationet 2024'!$D:$D,$C46,'OTH Preparationet 2024'!$H:$H,$F46,'OTH Preparationet 2024'!$M:$M,$H46,'OTH Preparationet 2024'!$L:$L,$J46,'OTH Preparationet 2024'!$Q:$Q,"")>0,1,0) -> 0
A47: GAE | B47: UAE | C47: UAE | D47: Region International | E47: WLO | F47: Wheel Loaders | H47: <12 | I47: Case | J47: =_xlfn.XLOOKUP(UPPER(TRIM(I47)),Sheet19!$A:$A,Sheet19!$B:$B,"") -> CAS | K47: Y | L47: P | M47: DES | N47: 1 | O47: 0 | P47: 0 | S47: =IF(COUNTIFS('OTH Preparationet 2024'!$D:$D,$C47,'OTH Preparationet 2024'!$H:$H,$F47,'OTH Preparationet 2024'!$M:$M,$H47,'OTH Preparationet 2024'!$L:$L,$J47,'OTH Preparationet 2024'!$Q:$Q,"")>0,1,0) -> 0
A48: GAE | B48: UAE | C48: UAE | D48: Region International | E48: WLO | F48: Wheel Loaders | H48: <12 | I48: Caterpillar Inc | J48: =_xlfn.XLOOKUP(UPPER(TRIM(I48)),Sheet19!$A:$A,Sheet19!$B:$B,"") | K48: Y | L48: P | M48: DES | N48: 14 | O48: 0 | P48: 0 | S48: =IF(COUNTIFS('OTH Preparationet 2024'!$D:$D,$C48,'OTH Preparationet 2024'!$H:$H,$F48,'OTH Preparationet 2024'!$M:$M,$H48,'OTH Preparationet 2024'!$L:$L,$J48,'OTH Preparationet 2024'!$Q:$Q,"")>0,1,0) -> 0
A49: GAE | B49: UAE | C49: UAE | D49: Region International | E49: WLO | F49: Wheel Loaders | H49: <12 | I49: Develon | J49: =_xlfn.XLOOKUP(UPPER(TRIM(I49)),Sheet19!$A:$A,Sheet19!$B:$B,"") -> DOO | K49: Y | L49: P | M49: DES | N49: 3 | O49: 0 | P49: 0 | S49: =IF(COUNTIFS('OTH Preparationet 2024'!$D:$D,$C49,'OTH Preparationet 2024'!$H:$H,$F49,'OTH Preparationet 2024'!$M:$M,$H49,'OTH Preparationet 2024'!$L:$L,$J49,'OTH Preparationet 2024'!$Q:$Q,"")>0,1,0) -> 0
A50: GAE | B50: UAE | C50: UAE | D50: Region International | E50: WLO | F50: Wheel Loaders | H50: <12 | I50: Hitachi | J50: =_xlfn.XLOOKUP(UPPER(TRIM(I50)),Sheet19!$A:$A,Sheet19!$B:$B,"") -> HIT | K50: Y | L50: P | M50: DES | N50: 2 | O50: 0 | P50: 0 | S50: =IF(COUNTIFS('OTH Preparationet 2024'!$D:$D,$C50,'OTH Preparationet 2024'!$H:$H,$F50,'OTH Preparationet 2024'!$M:$M,$H50,'OTH Preparationet 2024'!$L:$L,$J50,'OTH Preparationet 2024'!$Q:$Q,"")>0,1,0) -> 0
A51: GAE | B51: UAE | C51: UAE | D51: Region International | E51: WLO | F51: Wheel Loaders | H51: <12 | I51: Hyundai | J51: =_xlfn.XLOOKUP(UPPER(TRIM(I51)),Sheet19!$A:$A,Sheet19!$B:$B,"") -> HYU | K51: Y | L51: P | M51: DES | N51: 1 | O51: 0 | P51: 0 | S51: =IF(COUNTIFS('OTH Preparationet 2024'!$D:$D,$C51,'OTH Preparationet 2024'!$H:$H,$F51,'OTH Preparationet 2024'!$M:$M,$H51,'OTH Preparationet 2024'!$L:$L,$J51,'OTH Preparationet 2024'!$Q:$Q,"")>0,1,0) -> 0
A52: GAE | B52: UAE | C52: UAE | D52: Region International | E52: WLO | F52: Wheel Loaders | H52: <12 | I52: JCB | J52: =_xlfn.XLOOKUP(UPPER(TRIM(I52)),Sheet19!$A:$A,Sheet19!$B:$B,"") -> JCB | K52: Y | L52: P | M52: DES | N52: 1 | O52: 0 | P52: 0 | S52: =IF(COUNTIFS('OTH Preparationet 2024'!$D:$D,$C52,'OTH Preparationet 2024'!$H:$H,$F52,'OTH Preparationet 2024'!$M:$M,$H52,'OTH Preparationet 2024'!$L:$L,$J52,'OTH Preparationet 2024'!$Q:$Q,"")>0,1,0) -> 0
A53: GAE | B53: UAE | C53: UAE | D53: Region International | E53: WLO | F53: Wheel Loaders | H53: <12 | I53: Komatsu | J53: =_xlfn.XLOOKUP(UPPER(TRIM(I53)),Sheet19!$A:$A,Sheet19!$B:$B,"") -> KOM | K53: Y | L53: P | M53: DES | N53: 16 | O53: 0 | P53: 0 | S53: =IF(COUNTIFS('OTH Preparationet 2024'!$D:$D,$C53,'OTH Preparationet 2024'!$H:$H,$F53,'OTH Preparationet 2024'!$M:$M,$H53,'OTH Preparationet 2024'!$L:$L,$J53,'OTH Preparationet 2024'!$Q:$Q,"")>0,1,0) -> 0
A54: GAE | B54: UAE | C54: UAE | D54: Region International | E54: WLO | F54: Wheel Loaders | H54: <12 | I54: Liugong | J54: =_xlfn.XLOOKUP(UPPER(TRIM(I54)),Sheet19!$A:$A,Sheet19!$B:$B,"") -> LIU | K54: Y | L54: P | M54: DES | N54: 13 | O54: 0 | P54: 0 | S54: =IF(COUNTIFS('OTH Preparationet 2024'!$D:$D,$C54,'OTH Preparationet 2024'!$H:$H,$F54,'OTH Preparationet 2024'!$M:$M,$H54,'OTH Preparationet 2024'!$L:$L,$J54,'OTH Preparationet 2024'!$Q:$Q,"")>0,1,0) -> 0
A55: GAE | B55: UAE | C55: UAE | D55: Region International | E55: WLO | F55: Wheel Loaders | H55: <12 | I55: Sany | J55: =_xlfn.XLOOKUP(UPPER(TRIM(I55)),Sheet19!$A:$A,Sheet19!$B:$B,"") -> SNY | K55: Y | L55: P | M55: DES | N55: 7 | O55: 0 | P55: 0 | S55: =IF(COUNTIFS('OTH Preparationet 2024'!$D:$D,$C55,'OTH Preparationet 2024'!$H:$H,$F55,'OTH Preparationet 2024'!$M:$M,$H55,'OTH Preparationet 2024'!$L:$L,$J55,'OTH Preparationet 2024'!$Q:$Q,"")>0,1,0) -> 0
A56: GAE | B56: UAE | C56: UAE | D56: Region International | E56: WLO | F56: Wheel Loaders | H56: <12 | I56: XCMG | J56: =_xlfn.XLOOKUP(UPPER(TRIM(I56)),Sheet19!$A:$A,Sheet19!$B:$B,"") -> XCM | K56: Y | L56: P | M56: DES | N56: 17 | O56: 0 | P56: 0 | S56: =IF(COUNTIFS('OTH Preparationet 2024'!$D:$D,$C56,'OTH Preparationet 2024'!$H:$H,$F56,'OTH Preparationet 2024'!$M:$M,$H56,'OTH Preparationet 2024'!$L:$L,$J56,'OTH Preparationet 2024'!$Q:$Q,"")>0,1,0) -> 0
A57: GAE | B57: UAE | C57: UAE | D57: Region International | E57: WLO | F57: Wheel Loaders | H57: >12 | I57: Case | J57: =_xlfn.XLOOKUP(UPPER(TRIM(I57)),Sheet19!$A:$A,Sheet19!$B:$B,"") -> CAS | K57: Y | L57: P | M57: DES | N57: 10 | O57: 0 | P57: 0 | S57: =IF(COUNTIFS('OTH Preparationet 2024'!$D:$D,$C57,'OTH Preparationet 2024'!$H:$H,$F57,'OTH Preparationet 2024'!$M:$M,$H57,'OTH Preparationet 2024'!$L:$L,$J57,'OTH Preparationet 2024'!$Q:$Q,"")>0,1,0) -> 0
...

Sheet OTH Preparationet 2024
A1: Year | B1: Source | C1: Country Code | D1: Country | E1: Country Grouping | F1: Region | G1: Market Area | H1: Machine Line Name | I1: Machine Line Code | J1: Artificial machine line | K1: Brand Name | L1: Brand Code | M1: Size Class Flag | N1: MS (%) | O1: Deletion flag | P1: Pri/Sec | Q1: Reporter flag | R1: FID
A2: 2024 | B2: DES | C2: AE | D2: UAE | E2: UAE | F2: Region International | G2: MA East | H2: Articulated Haulers | I2: 330 | J2: Articulated Haulers | K2: CATERPILLAR | L2: CAT | P2: P | Q2: Y | R2: 18
A3: 2024 | B3: DES | C3: AE | D3: UAE | E3: UAE | F3: Region International | G3: MA East | H3: Articulated Haulers | I3: 330 | J3: Articulated Haulers | K3: DEVELON | L3: DOO | P3: P | Q3: Y | R3: 4
A4: 2024 | B4: DES | C4: AE | D4: UAE | E4: UAE | F4: Region International | G4: MA East | H4: Articulated Haulers | I4: 330 | J4: Articulated Haulers | K4: KOMATSU | L4: KOM | P4: P | Q4: Y | R4: 80
A5: 2024 | B5: DES | C5: AE | D5: UAE | E5: UAE | F5: Region International | G5: MA East | H5: Articulated Haulers | I5: 330 | J5: Articulated Haulers | K5: VOLVO | L5: VCE | P5: P | Q5: Y | R5: 129
A6: 2024 | B6: DES | C6: AE | D6: UAE | E6: UAE | F6: Region International | G6: MA East | H6: Compact Excavators | I6: CEX | J6: CEX | K6: BOBCAT | L6: BOB | M6: <10T | P6: P | Q6: Y | R6: 13
A7: 2024 | B7: DES | C7: AE | D7: UAE | E7: UAE | F7: Region International | G7: MA East | H7: Compact Excavators | I7: CEX | J7: CEX | K7: CATERPILLAR | L7: CAT | M7: <10T | P7: P | Q7: Y | R7: 31
A8: 2024 | B8: DES | C8: AE | D8: UAE | E8: UAE | F8: Region International | G8: MA East | H8: Compact Excavators | I8: CEX | J8: CEX | K8: DEVELON | L8: DOO | M8: <10T | P8: P | Q8: Y | R8: 3
A9: 2024 | B9: DES | C9: AE | D9: UAE | E9: UAE | F9: Region International | G9: MA East | H9: Compact Excavators | I9: CEX | J9: CEX | K9: HITACHI | L9: HIT | M9: <10T | P9: P | Q9: Y | R9: 34
A10: 2024 | B10: DES | C10: AE | D10: UAE | E10: UAE | F10: Region International | G10: MA East | H10: Compact Excavators | I10: CEX | J10: CEX | K10: JCB | L10: JCB | M10: <10T | P10: P | Q10: Y | R10: 10
A11: 2024 | B11: DES | C11: AE | D11: UAE | E11: UAE | F11: Region International | G11: MA East | H11: Compact Excavators | I11: CEX | J11: CEX | K11: KOBELCO | L11: KOB | M11: <10T | P11: P | Q11: Y | R11: 25
A12: 2024 | B12: DES | C12: AE | D12: UAE | E12: UAE | F12: Region International | G12: MA East | H12: Compact Excavators | I12: CEX | J12: CEX | K12: LIUGONG | L12: LIU | M12: <10T | P12: P | Q12: Y | R12: 10
A13: 2024 | B13: DES | C13: AE | D13: UAE | E13: UAE | F13: Region International | G13: MA East | H13: Compact Excavators | I13: CEX | J13: CEX | K13: SANY | L13: SNY | M13: <10T | P13: P | Q13: Y | R13: 10
A14: 2024 | B14: DES | C14: AE | D14: UAE | E14: UAE | F14: Region International | G14: MA East | H14: Compact Excavators | I14: CEX | J14: CEX | K14: TAKEUCHI | L14: TAK | M14: <10T | P14: P | Q14: Y | R14: 53
